Workbook

Sheet Daily
A1: Brent | B1: Rotterdam HFO380 | C1: Brent
A2: 35797 | B2: =_xlfn.XLOOKUP(A2,bunker_daily_raw!A2:A3818,bunker_daily_raw!B2:B3818) -> #N/A | C2: 15.77
A3: 35800 | B3: =_xlfn.XLOOKUP(A3,bunker_daily_raw!$A$2:$A$3819,bunker_daily_raw!$B$2:$B$3819) -> 69 | C3: 15.29
A4: 35801 | B4: =_xlfn.XLOOKUP(A4,bunker_daily_raw!$A$2:$A$3819,bunker_daily_raw!$B$2:$B$3819) -> 69.5 | C4: 15.48
A5: 35802 | B5: =_xlfn.XLOOKUP(A5,bunker_daily_raw!$A$2:$A$3819,bunker_daily_raw!$B$2:$B$3819) -> 63.5 | C5: 15.33
A6: 35803 | B6: =_xlfn.XLOOKUP(A6,bunker_daily_raw!$A$2:$A$3819,bunker_daily_raw!$B$2:$B$3819) -> 63.25 | C6: 15.47
A7: 35804 | B7: =_xlfn.XLOOKUP(A7,bunker_daily_raw!$A$2:$A$3819,bunker_daily_raw!$B$2:$B$3819) -> 60.5 | C7: 15.33
A8: 35807 | B8: =_xlfn.XLOOKUP(A8,bunker_daily_raw!$A$2:$A$3819,bunker_daily_raw!$B$2:$B$3819) -> 62.5 | C8: 15.07
A9: 35808 | B9: =_xlfn.XLOOKUP(A9,bunker_daily_raw!$A$2:$A$3819,bunker_daily_raw!$B$2:$B$3819) -> 63.5 | C9: 15.08
A10: 35809 | B10: =_xlfn.XLOOKUP(A10,bunker_daily_raw!$A$2:$A$3819,bunker_daily_raw!$B$2:$B$3819) -> 63.5 | C10: 14.81
A11: 35810 | B11: =_xlfn.XLOOKUP(A11,bunker_daily_raw!$A$2:$A$3819,bunker_daily_raw!$B$2:$B$3819) -> 65 | C11: 14.75
A12: 35811 | B12: =_xlfn.XLOOKUP(A12,bunker_daily_raw!$A$2:$A$3819,bunker_daily_raw!$B$2:$B$3819) -> 64.5 | C12: 14.89
A13: 35814 | B13: =_xlfn.XLOOKUP(A13,bunker_daily_raw!$A$2:$A$3819,bunker_daily_raw!$B$2:$B$3819) -> 67 | C13: 15.38
A14: 35815 | B14: =_xlfn.XLOOKUP(A14,bunker_daily_raw!$A$2:$A$3819,bunker_daily_raw!$B$2:$B$3819) -> 67 | C14: 14.95
... A71: 35894 | B71: =_xlfn.XLOOKUP(A71,bunker_daily_raw!$A$2:$A$3819,bunker_daily_raw!$B$2:$B$3819) -> 75.75 | C71: 13.23
A72: 35895 | B72: =_xlfn.XLOOKUP(A72,bunker_daily_raw!$A$2:$A$3819,bunker_daily_raw!$B$2:$B$3819) -> #N/A
A73: 35898 | B73: =_xlfn.XLOOKUP(A73,bunker_daily_raw!$A$2:$A$3819,bunker_daily_raw!$B$2:$B$3819) -> 75.75
A74: 35899 | B74: =_xlfn.XLOOKUP(A74,bunker_daily_raw!$A$2:$A$3819,bunker_daily_raw!$B$2:$B$3819) -> 77.5 | C74: 13.15
A75: 35900 | B75: =_xlfn.XLOOKUP(A75,bunker_daily_raw!$A$2:$A$3819,bunker_daily_raw!$B$2:$B$3819) -> 75 | C75: 13.31
A76: 35901 | B76: =_xlfn.XLOOKUP(A76,bunker_daily_raw!$A$2:$A$3819,bunker_daily_raw!$B$2:$B$3819) -> 71.75 | C76: 13.68
A77: 35902 | B77: =_xlfn.XLOOKUP(A77,bunker_daily_raw!$A$2:$A$3819,bunker_daily_raw!$B$2:$B$3819) -> 70.5 | C77: 14.06
A78: 35905 | B78: =_xlfn.XLOOKUP(A78,bunker_daily_raw!$A$2:$A$3819,bunker_daily_raw!$B$2:$B$3819) -> 69 | C78: 13.82
A79: 35906 | B79: =_xlfn.XLOOKUP(A79,bunker_daily_raw!$A$2:$A$3819,bunker_daily_raw!$B$2:$B$3819) -> 69 | C79: 13.95
A80: 35907 | B80: =_xlfn.XLOOKUP(A80,bunker_daily_raw!$A$2:$A$3819,bunker_daily_raw!$B$2:$B$3819) -> 70.25 | C80: 13.71
A81: 35908 | B81: =_xlfn.XLOOKUP(A81,bunker_daily_raw!$A$2:$A$3819,bunker_daily_raw!$B$2:$B$3819) -> 68.5 | C81: 13.42
A82: 35909 | B82: =_xlfn.XLOOKUP(A82,bunker_daily_raw!$A$2:$A$3819,bunker_daily_raw!$B$2:$B$3819) -> 69 | C82: 13.32
A83: 35912 | B83: =_xlfn.XLOOKUP(A83,bunker_daily_raw!$A$2:$A$3819,bunker_daily_raw!$B$2:$B$3819) -> 69.5 | C83: 13.65
A84: 35913 | B84: =_xlfn.XLOOKUP(A84,bunker_daily_raw!$A$2:$A$3819,bunker_daily_raw!$B$2:$B$3819) -> 67.5 | C84: 13.88
A85: 35914 | B85: =_xlfn.XLOOKUP(A85,bunker_daily_raw!$A$2:$A$3819,bunker_daily_raw!$B$2:$B$3819) -> 66.25 | C85: 14.09
... A87: 35916 | B87: =_xlfn.XLOOKUP(A87,bunker_daily_raw!$A$2:$A$3819,bunker_daily_raw!$B$2:$B$3819) -> #N/A | C87: 14.6
A88: 35919 | B88: =_xlfn.XLOOKUP(A88,bunker_daily_raw!$A$2:$A$3819,bunker_daily_raw!$B$2:$B$3819) -> 63.5
A89: 35920 | B89: =_xlfn.XLOOKUP(A89,bunker_daily_raw!$A$2:$A$3819,bunker_daily_raw!$B$2:$B$3819) -> 63.5 | C89: 14.13
A90: 35921 | B90: =_xlfn.XLOOKUP(A90,bunker_daily_raw!$A$2:$A$3819,bunker_daily_raw!$B$2:$B$3819) -> 65.75 | C90: 13.91
A91: 35922 | B91: =_xlfn.XLOOKUP(A91,bunker_daily_raw!$A$2:$A$3819,bunker_daily_raw!$B$2:$B$3819) -> 67.25 | C91: 13.81
A92: 35923 | B92: =_xlfn.XLOOKUP(A92,bunker_daily_raw!$A$2:$A$3819,bunker_daily_raw!$B$2:$B$3819) -> 65 | C92: 13.94
A93: 35926 | B93: =_xlfn.XLOOKUP(A93,bunker_daily_raw!$A$2:$A$3819,bunker_daily_raw!$B$2:$B$3819) -> #N/A | C93: 14.41
A94: 35927 | B94: =_xlfn.XLOOKUP(A94,bunker_daily_raw!$A$2:$A$3819,bunker_daily_raw!$B$2:$B$3819) -> 64.25 | C94: 14.75
A95: 35928 | B95: =_xlfn.XLOOKUP(A95,bunker_daily_raw!$A$2:$A$3819,bunker_daily_raw!$B$2:$B$3819) -> 63.5 | C95: 14.15
A96: 35929 | B96: =_xlfn.XLOOKUP(A96,bunker_daily_raw!$A$2:$A$3819,bunker_daily_raw!$B$2:$B$3819) -> 64.5 | C96: 14.29
A97: 35930 | B97: =_xlfn.XLOOKUP(A97,bunker_daily_raw!$A$2:$A$3819,bunker_daily_raw!$B$2:$B$3819) -> 63.5 | C97: 14.33
...

Sheet Monthly
A1: Date | B1: Rotterdam HFO380cst | C1: Brent
A2: 32874 | B2: 92.875 | C2: =bunker_monthly_cal!Q34 -> 21.7925
A3: 32905 | B3: 89.5 | C3: =bunker_monthly_cal!Q35 -> 19.785
A4: 32933 | B4: 84.3 | C4: =bunker_monthly_cal!Q36 -> 18.418
A5: 32964 | B5: 78.25 | C5: =bunker_monthly_cal!Q37 -> 12.47
A6: 32994 | B6: 75.375 | C6: =bunker_monthly_cal!Q38 -> 16.335
A7: 33025 | B7: 60.2 | C7: =bunker_monthly_cal!Q39 -> 15.278
A8: 33055 | B8: 70.75 | C8: =bunker_monthly_cal!Q40 -> 17.3525
A9: 33086 | B9: 113.6 | C9: =bunker_monthly_cal!Q41 -> 27.666
A10: 33117 | B10: 133.625 | C10: =bunker_monthly_cal!Q42 -> 35.6875
A11: 33147 | B11: 142.625 | C11: =bunker_monthly_cal!Q43 -> 36.47
A12: 33178 | B12: 138.7 | C12: =bunker_monthly_cal!Q44 -> 32.62
A13: 33208 | B13: 143.625 | C13: =bunker_monthly_cal!Q45 -> 27.77
... A418: 45536 | B418: 422.5625 | C418: =bunker_monthly_cal!Q450 -> 73.5225

Sheet bunker_weekly_raw
A1: Date | B1: Rotterdam HFO380cst | D1: Date | E1: Brent
A2: 35800 | B2: 69 | D2: 31917 | E2: 18.63
A3: 35801 | B3: 69.5 | D3: 31918 | E3: 18.45
A4: 35802 | B4: 63.5 | D4: 31919 | E4: 18.55
A5: 35803 | B5: 63.25 | D5: 31922 | E5: 18.6
A6: 35804 | B6: 60.5 | D6: 31923 | E6: 18.63
A7: 35807 | B7: 62.5 | D7: 31924 | E7: 18.6
A8: 35808 | B8: 63.5 | D8: 31925 | E8: 18.6
A9: 35809 | B9: 63.5 | D9: 31926 | E9: 18.58
A10: 35810 | B10: 65 | D10: 31929 | E10: 18.65
A11: 35811 | B11: 64.5 | D11: 31930 | E11: 18.68
A12: 35814 | B12: 67 | D12: 31931 | E12: 18.75
A13: 35815 | B13: 67 | D13: 31932 | E13: 18.78
... A19: 35828 | B19: 64.25 | D19: 31940 | E19: 18.78
A20: 35829 | B20: 63.5 | D20: 31943
A21: 35830 | B21: 64 | D21: 31944 | E21: 18.9
A22: 35831 | B22: 67 | D22: 31945 | E22: 19.03
A23: 35832 | B23: 65.5 | D23: 31946 | E23: 19.05
A24: 35835 | B24: 67 | D24: 31947 | E24: 19.05
A25: 35836 | B25: 66 | D25: 31950 | E25: 19.1
A26: 35837 | B26: 66 | D26: 31951 | E26: 18.9
A27: 35838 | B27: 67 | D27: 31952 | E27: 18.75
A28: 35839 | B28: 67.5 | D28: 31953 | E28: 18.7
A29: 35842 | B29: 64.25 | D29: 31954 | E29: 19.08
A30: 35843 | B30: 65.5 | D30: 31957 | E30: 19.15
A31: 35844 | B31: 65 | D31: 31958 | E31: 19.08
A32: 35845 | B32: 64.75 | D32: 31959 | E32: 18.98
... A158: 36028 | B158: 60 | D158: 32135 | E158: 17.1
A159: 36031 | B159: 62 | D159: 32136
A160: 36032 | B160: 66 | D160: 32139 | E160: 17
A161: 36033 | B161: 65.25 | D161: 32140 | E161: 17.38
A162: 36034 | B162: 64.5 | D162: 32141 | E162: 17.85
A163: 36035 | B163: 66 | D163: 32142 | E163: 17.6
A164: 36038 | B164: 66.25 | D164: 32143
A165: 36039 | B165: 67 | D165: 32146 | E165: 17.95
A166: 36040 | B166: 70.75 | D166: 32147 | E166: 17.08
A167: 36041 | B167: 69 | D167: 32148 | E167: 17.9
A168: 36042 | B168: 71 | D168: 32149
A169: 36045 | B169: 70 | D169: 32150 | E169: 16.88
A170: 36046 | B170: 70.75 | D170: 32153 | E170: 16.65
...

Sheet bunker_daily_raw
A1: Date | B1: Rotterdam HFO380cst
A2: 35800 | B2: 69
A3: 35801 | B3: 69.5
A4: 35802 | B4: 63.5
A5: 35803 | B5: 63.25
A6: 35804 | B6: 60.5
A7: 35807 | B7: 62.5
A8: 35808 | B8: 63.5
A9: 35809 | B9: 63.5
A10: 35810 | B10: 65
A11: 35811 | B11: 64.5
A12: 35814 | B12: 67
A13: 35815 | B13: 67
... A3608: 41054 | B3608: 612.5
A3609: 41057 | B3609: =VLOOKUP(A3609,Daily!F$3607:G$4751,2,0) -> #N/A
A3610: 41058 | B3610: =VLOOKUP(A3610,Daily!F$3607:G$4751,2,0) -> #N/A
A3611: 41059 | B3611: =VLOOKUP(A3611,Daily!F$3607:G$4751,2,0) -> #N/A
A3612: 41060 | B3612: =VLOOKUP(A3612,Daily!F$3607:G$4751,2,0) -> #N/A
A3613: 41061 | B3613: =VLOOKUP(A3613,Daily!F$3607:G$4751,2,0) -> #N/A
A3614: 41066 | B3614: =VLOOKUP(A3614,Daily!F$3607:G$4751,2,0) -> #N/A
A3615: 41067 | B3615: =VLOOKUP(A3615,Daily!F$3607:G$4751,2,0) -> #N/A
A3616: 41068 | B3616: =VLOOKUP(A3616,Daily!F$3607:G$4751,2,0) -> #N/A
A3617: 41071 | B3617: =VLOOKUP(A3617,Daily!F$3607:G$4751,2,0) -> #N/A
A3618: 41072 | B3618: =VLOOKUP(A3618,Daily!F$3607:G$4751,2,0) -> #N/A
A3619: 41073 | B3619: =VLOOKUP(A3619,Daily!F$3607:G$4751,2,0) -> #N/A
A3620: 41074 | B3620: =VLOOKUP(A3620,Daily!F$3607:G$4751,2,0) -> #N/A
... A3652: 41120 | B3652: =VLOOKUP(A3652,Daily!F$3607:G$4751,2,0) -> #N/A
A3653: 41121 | B3653: 605
A3654: 41122 | B3654: 607
A3655: 41123 | B3655: 609
A3656: 41124 | B3656: 625
A3657: 41127 | B3657: 628
A3658: 41128 | B3658: 641
A3659: 41129 | B3659: 643
A3660: 41130 | B3660: 647
A3661: 41131 | B3661: 645
A3662: 41134 | B3662: 651
A3663: 41135 | B3663: 653
A3664: 41136 | B3664: 660
... A3666: 41138 | B3666: 667
...

Sheet bunker_monthly_cal
A1: Date | B1: Rotterdam HFO380cst | E1: brent | G1: EOW Date | H1: EOW brent | I1: month | J1: year | M1: Monthly brent | O1: Monthly brent sorted (manualy sorted)
A2: 32874 | B2: 92.875 | D2: 31917 | E2: 18.63 | G2: =D4 -> 31919 | H2: =_xlfn.XLOOKUP(G2,D:D,E:E) -> 18.55 | I2: =MONTH(G2) -> 5 | J2: =YEAR(G2) -> 1987 | K2: {=_xlfn.GROUPBY(I2:J2006,H2:H2006,_xleta.AVERAGE)} -> 1 | L2: 1988 | M2: 13.302 | O2: 5 | P2: 1987 | Q2: 18.565
A3: 32905 | B3: 89.5 | D3: 31918 | E3: 18.45 | G3: =G2+7 -> 31926 | H3: =_xlfn.XLOOKUP(G3,D:D,E:E) -> 18.58 | I3: =MONTH(G3) -> 5 | J3: =YEAR(G3) -> 1987 | K3: 1 | L3: 1989 | M3: 17.395 | O3: 6 | P3: 1987 | Q3: 18.89
A4: 32933 | B4: 84.3 | D4: 31919 | E4: 18.55 | G4: =G3+7 -> 31933 | H4: =_xlfn.XLOOKUP(G4,D:D,E:E) -> 18.65 | I4: =MONTH(G4) -> 6 | J4: =YEAR(G4) -> 1987 | K4: 1 | L4: 1990 | M4: 21.7925 | O4: 7 | P4: 1987 | Q4: 19.86
A5: 32964 | B5: 78.25 | D5: 31922 | E5: 18.6 | G5: =G4+7 -> 31940 | H5: =_xlfn.XLOOKUP(G5,D:D,E:E) -> 18.78 | I5: =MONTH(G5) -> 6 | J5: =YEAR(G5) -> 1987 | K5: 1 | L5: 1991 | M5: 22.5075 | O5: 8 | P5: 1987 | Q5: 18.8
A6: 32994 | B6: 75.375 | D6: 31923 | E6: 18.63 | G6: =G5+7 -> 31947 | H6: =_xlfn.XLOOKUP(G6,D:D,E:E) -> 19.05 | I6: =MONTH(G6) -> 6 | J6: =YEAR(G6) -> 1987 | K6: 1 | L6: 1992 | M6: 18.138 | O6: 9 | P6: 1987 | Q6: 18.3025
A7: 33025 | B7: 60.2 | D7: 31924 | E7: 18.6 | G7: =G6+7 -> 31954 | H7: =_xlfn.XLOOKUP(G7,D:D,E:E) -> 19.08 | I7: =MONTH(G7) -> 6 | J7: =YEAR(G7) -> 1987 | K7: 1 | L7: 1993 | M7: 14.014 | O7: 10 | P7: 1987 | Q7: 18.806
A8: 33055 | B8: 70.75 | D8: 31925 | E8: 18.6 | G8: =G7+7 -> 31961 | H8: =_xlfn.XLOOKUP(G8,D:D,E:E) -> 19.33 | I8: =MONTH(G8) -> 7 | J8: =YEAR(G8) -> 1987 | K8: 1 | L8: 1994 | M8: 14.4025 | O8: 11 | P8: 1987 | Q8: 17.7825
A9: 33086 | B9: 113.6 | D9: 31926 | E9: 18.58 | G9: =G8+7 -> 31968 | H9: =_xlfn.XLOOKUP(G9,D:D,E:E) -> 19.73 | I9: =MONTH(G9) -> 7 | J9: =YEAR(G9) -> 1987 | K9: 1 | L9: 1995 | M9: 16.54 | O9: 12 | P9: 1987 | Q9: 12.8325
A10: 33117 | B10: 133.625 | D10: 31929 | E10: 18.65 | G10: =G9+7 -> 31975 | H10: =_xlfn.XLOOKUP(G10,D:D,E:E) -> 20.63 | I10: =MONTH(G10) -> 7 | J10: =YEAR(G10) -> 1987 | K10: 1 | L10: 1996 | M10: 17.8275 | O10: 1 | P10: 1988 | Q10: 13.302
A11: 33147 | B11: 142.625 | D11: 31930 | E11: 18.68 | G11: =G10+7 -> 31982 | H11: =_xlfn.XLOOKUP(G11,D:D,E:E) -> 19.58 | I11: =MONTH(G11) -> 7 | J11: =YEAR(G11) -> 1987 | K11: 1 | L11: 1997 | M11: 23.472 | O11: 2 | P11: 1988 | Q11: 15.5125
A12: 33178 | B12: 138.7 | D12: 31931 | E12: 18.75 | G12: =G11+7 -> 31989 | H12: =_xlfn.XLOOKUP(G12,D:D,E:E) -> 20.03 | I12: =MONTH(G12) -> 7 | J12: =YEAR(G12) -> 1987 | K12: 1 | L12: 1998 | M12: 15.168 | O12: 3 | P12: 1988 | Q12: 14.815
A13: 33208 | B13: 143.625 | D13: 31932 | E13: 18.78 | G13: =G12+7 -> 31996 | H13: =_xlfn.XLOOKUP(G13,D:D,E:E) -> 19.65 | I13: =MONTH(G13) -> 8 | J13: =YEAR(G13) -> 1987 | K13: 1 | L13: 1999 | M13: 9.048 | O13: 4 | P13: 1988 | Q13: 13.23
A14: 33239 | B14: 142.375 | D14: 31933 | E14: 18.65 | G14: =G13+7 -> 32003 | H14: =_xlfn.XLOOKUP(G14,D:D,E:E) -> 19.25 | I14: =MONTH(G14) -> 8 | J14: =YEAR(G14) -> 1987 | K14: 1 | L14: 2000 | M14: 25.655 | O14: 5 | P14: 1988 | Q14: 16.4125
... A19: 33390 | B19: 91.875 | D19: 31940 | E19: 18.78 | G19: =G18+7 -> 32038 | H19: =_xlfn.XLOOKUP(G19,D:D,E:E) -> 18.3 | I19: =MONTH(G19) -> 9 | J19: =YEAR(G19) -> 1987 | K19: 1 | L19: 2005 | M19: 44.7925 | O19: 10 | P19: 1988 | Q19: 12.6575
A20: 33420 | B20: 71.625 | D20: 31943 | G20: =G19+7 -> 32045 | H20: =_xlfn.XLOOKUP(G20,D:D,E:E) -> 18.6 | I20: =MONTH(G20) -> 9 | J20: =YEAR(G20) -> 1987 | K20: 1 | L20: 2006 | M20: 63.47 | O20: 11 | P20: 1988 | Q20: 13.14
A21: 33451 | B21: 69.4 | D21: 31944 | E21: 18.9 | G21: =G20+7 -> 32052 | H21: =_xlfn.XLOOKUP(G21,D:D,E:E) -> 18.65 | I21: =MONTH(G21) -> 10 | J21: =YEAR(G21) -> 1987 | K21: 1 | L21: 2007 | M21: 52.5875 | O21: 12 | P21: 1988 | Q21: 15.382
A22: 33482 | B22: 69.1875 | D22: 31945 | E22: 19.03 | G22: =G21+7 -> 32059 | H22: =_xlfn.XLOOKUP(G22,D:D,E:E) -> 18.6 | I22: =MONTH(G22) -> 10 | J22: =YEAR(G22) -> 1987 | K22: 1 | L22: 2008 | M22: 92.3375 | O22: 1 | P22: 1989 | Q22: 17.395
A23: 33512 | B23: 80.0625 | D23: 31946 | E23: 19.05 | G23: =G22+7 -> 32066 | H23: =_xlfn.XLOOKUP(G23,D:D,E:E) -> 19 | I23: =MONTH(G23) -> 10 | J23: =YEAR(G23) -> 1987 | K23: 1 | L23: 2009 | M23: 43.2 | O23: 2 | P23: 1989 | Q23: 16.8375
A24: 33543 | B24: 88 | D24: 31947 | E24: 19.05 | G24: =G23+7 -> 32073 | H24: =_xlfn.XLOOKUP(G24,D:D,E:E) -> 18.98 | I24: =MONTH(G24) -> 10 | J24: =YEAR(G24) -> 1987 | K24: 1 | L24: 2010 | M24: 60.168 | O24: 3 | P24: 1989 | Q24: 15.022
A25: 33573 | B25: 74.25 | D25: 31950 | E25: 19.1 | G25: =G24+7 -> 32080 | H25: =_xlfn.XLOOKUP(G25,D:D,E:E) -> 18.8 | I25: =MONTH(G25) -> 10 | J25: =YEAR(G25) -> 1987 | K25: 1 | L25: 2011 | M25: 96.5025 | O25: 4 | P25: 1989 | Q25: 20.195
A26: 33604 | B26: 66.3 | D26: 31951 | E26: 18.9 | G26: =G25+7 -> 32087 | H26: =_xlfn.XLOOKUP(G26,D:D,E:E) -> 17.95 | I26: =MONTH(G26) -> 11 | J26: =YEAR(G26) -> 1987 | K26: 1 | L26: 2012 | M26: 110.21 | O26: 5 | P26: 1989 | Q26: 18.6375
A27: 33635 | B27: 66 | D27: 31952 | E27: 18.75 | G27: =G26+7 -> 32094 | H27: =_xlfn.XLOOKUP(G27,D:D,E:E) -> 17.8 | I27: =MONTH(G27) -> 11 | J27: =YEAR(G27) -> 1987 | K27: 1 | L27: 2013 | M27: 112.1175 | O27: 6 | P27: 1989 | Q27: 17.812
A28: 33664 | B28: 74.16667 | D28: 31953 | E28: 18.7 | G28: =G27+7 -> 32101 | H28: =_xlfn.XLOOKUP(G28,D:D,E:E) -> 17.6 | I28: =MONTH(G28) -> 11 | J28: =YEAR(G28) -> 1987 | K28: 1 | L28: 2014 | M28: 107.752 | O28: 7 | P28: 1989 | Q28: 17.49
A29: 33695 | B29: 75 | D29: 31954 | E29: 19.08 | G29: =G28+7 -> 32108 | H29: =_xlfn.XLOOKUP(G29,D:D,E:E) -> 17.78 | I29: =MONTH(G29) -> 11 | J29: =YEAR(G29) -> 1987 | K29: 1 | L29: 2015 | M29: 48.922 | O29: 8 | P29: 1989 | Q29: 16.7325
A30: 33725 | B30: 81.5 | D30: 31957 | E30: 19.15 | G30: =G29+7 -> 32115 | H30: =_xlfn.XLOOKUP(G30,D:D,E:E) -> 18 | I30: =MONTH(G30) -> 12 | J30: =YEAR(G30) -> 1987 | K30: 1 | L30: 2016 | M30: 24.814 | O30: 9 | P30: 1989 | Q30: 17.76
A31: 33756 | B31: 91.875 | D31: 31958 | E31: 19.08 | G31: =G30+7 -> 32122 | H31: =_xlfn.XLOOKUP(G31,D:D,E:E) -> 17.73 | I31: =MONTH(G31) -> 12 | J31: =YEAR(G31) -> 1987 | K31: 1 | L31: 2017 | M31: 55.0275 | O31: 10 | P31: 1989 | Q31: 18.9875
A32: 33786 | B32: 90 | D32: 31959 | E32: 18.98 | G32: =G31+7 -> 32129 | H32: =_xlfn.XLOOKUP(G32,D:D,E:E) -> 15.6 | I32: =MONTH(G32) -> 12 | J32: =YEAR(G32) -> 1987 | K32: 1 | L32: 2018 | M32: 69.0725 | O32: 11 | P32: 1989 | Q32: 18.82
... A158: 37622 | B158: 173.5 | D158: 32135 | E158: 17.1 | G158: =G157+7 -> 33011 | H158: =_xlfn.XLOOKUP(G158,D:D,E:E) -> 17.08 | I158: =MONTH(G158) -> 5 | J158: =YEAR(G158) -> 1990 | K158: 5 | L158: 1991 | M158: 19.132 | O158: 5 | P158: 2000 | Q158: 28.0025
A159: 37653 | B159: 175.125 | D159: 32136 | G159: =G158+7 -> 33018 | H159: =_xlfn.XLOOKUP(G159,D:D,E:E) -> 15.95 | I159: =MONTH(G159) -> 5 | J159: =YEAR(G159) -> 1990 | K159: 5 | L159: 1992 | M159: 19.888 | O159: 6 | P159: 2000 | Q159: 29.926
A160: 37681 | B160: 148.25 | D160: 32139 | E160: 17 | G160: =G159+7 -> 33025 | H160: =_xlfn.XLOOKUP(G160,D:D,E:E) -> 15.43 | I160: =MONTH(G160) -> 6 | J160: =YEAR(G160) -> 1990 | K160: 5 | L160: 1993 | M160: 18.465 | O160: 7 | P160: 2000 | Q160: 28.52
A161: 37712 | B161: 126.375 | D161: 32140 | E161: 17.38 | G161: =G160+7 -> 33032 | H161: =_xlfn.XLOOKUP(G161,D:D,E:E) -> 14.68 | I161: =MONTH(G161) -> 6 | J161: =YEAR(G161) -> 1990 | K161: 5 | L161: 1994 | M161: 16.265 | O161: 8 | P161: 2000 | Q161: 30.3675
A162: 37742 | B162: 137.9 | D162: 32141 | E162: 17.85 | G162: =G161+7 -> 33039 | H162: =_xlfn.XLOOKUP(G162,D:D,E:E) -> 15.15 | I162: =MONTH(G162) -> 6 | J162: =YEAR(G162) -> 1990 | K162: 5 | L162: 1995 | M162: 18.3275 | O162: 9 | P162: 2000 | Q162: 33.01
A163: 37773 | B163: 147.5 | D163: 32142 | E163: 17.6 | G163: =G162+7 -> 33046 | H163: =_xlfn.XLOOKUP(G163,D:D,E:E) -> 15.4 | I163: =MONTH(G163) -> 6 | J163: =YEAR(G163) -> 1990 | K163: 5 | L163: 1996 | M163: 18.898 | O163: 10 | P163: 2000 | Q163: 31.1475
A164: 37803 | B164: 170.5 | D164: 32143 | G164: =G163+7 -> 33053 | H164: =_xlfn.XLOOKUP(G164,D:D,E:E) -> 15.73 | I164: =MONTH(G164) -> 6 | J164: =YEAR(G164) -> 1990 | K164: 5 | L164: 1997 | M164: 19.046 | O164: 11 | P164: 2000 | Q164: 32.3775
A165: 37834 | B165: 159.7 | D165: 32146 | E165: 17.95 | G165: =G164+7 -> 33060 | H165: =_xlfn.XLOOKUP(G165,D:D,E:E) -> 15.35 | I165: =MONTH(G165) -> 7 | J165: =YEAR(G165) -> 1990 | K165: 5 | L165: 1998 | M165: 14.246 | O165: 12 | P165: 2000 | Q165: 25.538
A166: 37865 | B166: 147.75 | D166: 32147 | E166: 17.08 | G166: =G165+7 -> 33067 | H166: =_xlfn.XLOOKUP(G166,D:D,E:E) -> 17.03 | I166: =MONTH(G166) -> 7 | J166: =YEAR(G166) -> 1990 | K166: 5 | L166: 1999 | M166: 15.02 | O166: 1 | P166: 2001 | Q166: 25.9325
A167: 37895 | B167: 151.9 | D167: 32148 | E167: 17.9 | G167: =G166+7 -> 33074 | H167: =_xlfn.XLOOKUP(G167,D:D,E:E) -> 18 | I167: =MONTH(G167) -> 7 | J167: =YEAR(G167) -> 1990 | K167: 5 | L167: 2000 | M167: 28.0025 | O167: 2 | P167: 2001 | Q167: 27.79
A168: 37926 | B168: 154.75 | D168: 32149 | G168: =G167+7 -> 33081 | H168: =_xlfn.XLOOKUP(G168,D:D,E:E) -> 19.03 | I168: =MONTH(G168) -> 7 | J168: =YEAR(G168) -> 1990 | K168: 5 | L168: 2001 | M168: 28.3875 | O168: 3 | P168: 2001 | Q168: 24.468
A169: 37956 | B169: 141 | D169: 32150 | E169: 16.88 | G169: =G168+7 -> 33088 | H169: =_xlfn.XLOOKUP(G169,D:D,E:E) -> 24.13 | I169: =MONTH(G169) -> 8 | J169: =YEAR(G169) -> 1990 | K169: 5 | L169: 2002 | M169: 25.154 | O169: 4 | P169: 2001 | Q169: 25.81
...

Sheet Brent raw 
A1: 31917 | B1: 18.63
A2: 31918 | B2: 18.45
A3: 31919 | B3: 18.55
A4: 31922 | B4: 18.6
A5: 31923 | B5: 18.63
A6: 31924 | B6: 18.6
A7: 31925 | B7: 18.6
A8: 31926 | B8: 18.58
A9: 31929 | B9: 18.65
A10: 31930 | B10: 18.68
A11: 31931 | B11: 18.75
A12: 31932 | B12: 18.78
... A18: 31940 | B18: 18.78
A19: 31943
A20: 31944 | B20: 18.9
A21: 31945 | B21: 19.03
A22: 31946 | B22: 19.05
A23: 31947 | B23: 19.05
A24: 31950 | B24: 19.1
A25: 31951 | B25: 18.9
A26: 31952 | B26: 18.75
A27: 31953 | B27: 18.7
A28: 31954 | B28: 19.08
A29: 31957 | B29: 19.15
A30: 31958 | B30: 19.08
A31: 31959 | B31: 18.98
... A157: 32135 | B157: 17.1
A158: 32136
A159: 32139 | B159: 17
A160: 32140 | B160: 17.38
A161: 32141 | B161: 17.85
A162: 32142 | B162: 17.6
A163: 32143
A164: 32146 | B164: 17.95
A165: 32147 | B165: 17.08
A166: 32148 | B166: 17.9
A167: 32149
A168: 32150 | B168: 16.88
A169: 32153 | B169: 16.65
A170: 32154 | B170: 15.95
...
